Workbook
Name A_impresión_IM: #REF!
Name FORM: #REF!

Sheet Tabla para copiar
A1: Tabla de deflactores
A2: Actualizada: | B2: 14 de julio de 2026
A3: Fórmula para deflactar: (valor corriente/deflactor)*100
B5: 1993=100 | C5: 1994=100 | D5: 1995=100 | E5: 1996=100 | F5: 1997=100 | G5: 1998=100 | H5: 1999=100 | I5: 2000=100 | J5: 2001=100 | K5: 2002=100 | L5: 2003=100 | M5: 2004=100 | N5: 2005=100 | O5: 2006=100 | P5: 2007=100 | Q5: 2008=100 | R5: 2009=100 | S5: 2010=100 | T5: 2011=100 | U5: 2012=100 | V5: 2013=100 | W5: 2014=100 | X5: 2015=100 | Y5: 2016=100 | Z5: 2017=100 | AA5: 2018=100 | AB5: 2019=100 | AC5: 2020=100 | AD5: 2021=100 | AE5: 2022=100 | AF5: 2023=100 | AG5: 2024=100 | AH5: 2025=100 | AI5: 2026 = 100
A6: 1993 | B6: 100 | C6: 92.284442 | D6: 66.482929 | E6: 52.474051 | F6: 44.570123 | G6: 38.516801 | H6: 33.400197 | I6: 30.172368 | J6: 28.338044 | K6: 26.860114 | L6: 25.757767 | M6: 23.823877 | N6: 22.49977 | O6: 21.204762 | P6: 19.980404 | Q6: 18.794406 | R6: 17.858023 | S6: 17.109817 | T6: 16.191801 | U6: 15.48829 | V6: 15.228809 | W6: 14.591403 | X6: 14.135473 | Y6: 13.325598 | Z6: 12.504362 | AA6: 11.885767 | AB6: 11.393673 | AC6: 10.890553 | AD6: 10.422781 | AE6: 9.7713589 | AF6: 9.3348873 | AG6: 8.9883996 | AH6: 8.593292 | AI6: 8.2787013
A7: 1994 | B7: 108.36063 | C7: 100 | D7: 72.041319 | E7: 56.86121 | F7: 48.296465 | G7: 41.737047 | H7: 36.192663 | I7: 32.694967 | J7: 30.707282 | K7: 29.105788 | L7: 27.911278 | M7: 25.815703 | N7: 24.380891 | O7: 22.977613 | P7: 21.650892 | Q7: 20.365736 | R7: 19.351066 | S7: 18.540305 | T7: 17.545537 | U7: 16.783208 | V7: 16.502033 | W7: 15.811335 | X7: 15.317287 | Y7: 14.439702 | Z7: 13.549805 | AA7: 12.879492 | AB7: 12.346256 | AC7: 11.801071 | AD7: 11.294191 | AE7: 10.588306 | AF7: 10.115342 | AG7: 9.7398861 | AH7: 9.3117451 | AI7: 8.9708527
A8: 1995 | B8: 150.41455 | C8: 138.80923 | D8: 100 | E8: 78.928608 | F8: 67.03995 | G8: 57.934873 | H8: 50.238757 | I8: 45.383632 | J8: 42.624542 | K8: 40.401519 | L8: 38.743429 | M8: 35.834578 | N8: 33.842928 | O8: 31.895048 | P8: 30.053436 | Q8: 28.269521 | R8: 26.861066 | S8: 25.735655 | T8: 24.354825 | U8: 23.296642 | V8: 22.906345 | W8: 21.947593 | X8: 21.261808 | Y8: 20.043638 | Z8: 18.80838 | AA8: 17.877924 | AB8: 17.137743 | AC8: 16.380976 | AD8: 15.67738 | AE8: 14.697546 | AF8: 14.041029 | AG8: 13.519861 | AH8: 12.925562 | AI8: 12.452371
A9: 1996 | B9: 190.57038 | C9: 175.86682 | D9: 126.69677 | E9: 100 | F9: 84.937454 | G9: 73.401616 | H9: 63.650885 | I9: 57.499598 | J9: 54.00392 | K9: 51.187422 | L9: 49.086675 | M9: 45.401254 | N9: 42.877897 | O9: 40.409997 | P9: 38.076733 | Q9: 35.816571 | R9: 34.032104 | S9: 32.606244 | T9: 30.856778 | U9: 29.516094 | V9: 29.0216 | W9: 27.806892 | X9: 26.938025 | Y9: 25.394643 | Z9: 23.829611 | AA9: 22.650753 | AB9: 21.712967 | AC9: 20.754168 | AD9: 19.862734 | AE9: 18.621316 | AF9: 17.789531 | AG9: 17.129228 | AH9: 16.37627 | AI9: 15.776753
A10: 1997 | B10: 224.36555 | C10: 207.05449 | D10: 149.16479 | E10: 117.73369 | F10: 100 | G10: 86.418431 | H10: 74.938536 | I10: 67.696399 | J10: 63.580808 | K10: 60.264841 | L10: 57.791555 | M10: 53.452573 | N10: 50.481731 | O10: 47.576181 | P10: 44.829144 | Q10: 42.168171 | R10: 40.067252 | S10: 38.388535 | T10: 36.328824 | U10: 34.750387 | V10: 34.1682 | W10: 32.73808 | X10: 31.715131 | Y10: 29.898051 | Z10: 28.055481 | AA10: 26.667567 | AB10: 25.563478 | AC10: 24.434648 | AD10: 23.38513 | AE10: 21.923563 | AF10: 20.944271 | AG10: 20.166872 | AH10: 19.280387 | AI10: 18.574554
A11: 1998 | B11: 259.62696 | C11: 239.59529 | D11: 172.60761 | E11: 136.23678 | F11: 115.71606 | G11: 100 | H11: 86.715918 | I11: 78.335603 | J11: 73.573203 | K11: 69.736097 | L11: 66.874107 | M11: 61.853208 | N11: 58.415468 | O11: 55.053279 | P11: 51.874517 | Q11: 48.795344 | R11: 46.364243 | S11: 44.421698 | T11: 42.038282 | U11: 40.211777 | V11: 39.538094 | W11: 37.883215 | X11: 36.699499 | Y11: 34.596845 | Z11: 32.464696 | AA11: 30.858657 | AB11: 29.581048 | AC11: 28.274811 | AD11: 27.06035 | AE11: 25.369082 | AF11: 24.235884 | AG11: 23.336309 | AH11: 22.310503 | AI11: 21.493741
A12: 1999 | B12: 299.39943 | C12: 276.29909 | D12: 199.04951 | E12: 157.10701 | F12: 133.44269 | G12: 115.31908 | H12: 100 | I12: 90.335898 | J12: 84.843942 | K12: 80.419026 | L12: 77.118606 | M12: 71.328552 | N12: 67.364181 | O12: 63.486936 | P12: 59.821216 | Q12: 56.270343 | R12: 53.46682 | S12: 51.226695 | T12: 48.47816 | U12: 46.371851 | V12: 45.594966 | W12: 43.686576 | X12: 42.321525 | Y12: 39.896764 | Z12: 37.437989 | AA12: 35.585919 | AB12: 34.112593 | AC12: 32.606253 | AD12: 31.205747 | AE12: 29.255393 | AF12: 27.948599 | AG12: 26.911217 | AH12: 25.728267 | AI12: 24.786384
A13: 2000 | B13: 331.42907 | C13: 305.85747 | D13: 220.34376 | E13: 173.91426 | F13: 147.71834 | G13: 127.65588 | H13: 110.69796 | I13: 100 | J13: 93.920516 | K13: 89.022225 | L13: 85.368728 | M13: 78.959255 | N13: 74.570778 | O13: 70.278746 | P13: 66.220869 | Q13: 62.290124 | R13: 59.186681 | S13: 56.706908 | T13: 53.664337 | U13: 51.332695 | V13: 50.4727 | W13: 48.36015 | X13: 46.849067 | Y13: 44.164906 | Z13: 41.443091 | AA13: 39.392889 | AB13: 37.761946 | AC13: 36.094458 | AD13: 34.544127 | AE13: 32.385124 | AF13: 30.93853 | AG13: 29.790169 | AH13: 28.480668 | AI13: 27.438023
A14: 2001 | B14: 352.88251 | C14: 325.65565 | D14: 234.60663 | E14: 185.17174 | F14: 157.28017 | G14: 135.91905 | H14: 117.86345 | I14: 106.47301 | J14: 100 | K14: 94.784642 | L14: 90.894653 | M14: 84.070295 | N14: 79.397751 | O14: 74.827896 | P14: 70.507352 | Q14: 66.32217 | R14: 63.01784 | S14: 60.377551 | T14: 57.138034 | U14: 54.655466 | V14: 53.739802 | W14: 51.490507 | X14: 49.881611 | Y14: 47.023704 | Z14: 44.125706 | AA14: 41.942794 | AB14: 40.20628 | AC14: 38.430856 | AD14: 36.780172 | AE14: 34.481416 | AF14: 32.941184 | AG14: 31.71849 | AH14: 30.324224 | AI14: 29.214089
A15: 2002 | B15: 372.29925 | C15: 343.57428 | D15: 247.51544 | E15: 195.36049 | F15: 165.93423 | G15: 143.39776 | H15: 124.34868 | I15: 112.3315 | J15: 105.50232 | K15: 100 | L15: 95.895972 | M15: 88.696115 | N15: 83.766472 | O15: 78.945169 | P15: 74.386895 | Q15: 69.97143 | R15: 66.485286 | S15: 63.69972 | T15: 60.281954 | U15: 57.662786 | V15: 56.69674 | W15: 54.323682 | X15: 52.626259 | Y15: 49.611101 | Z15: 46.553646 | AA15: 44.250622 | AB15: 42.41856 | AC15: 40.545446 | AD15: 38.803936 | AE15: 36.378696 | AF15: 34.753715 | AG15: 33.463744 | AH15: 31.992761 | AI15: 30.821542
A16: 2003 | B16: 388.23241 | C16: 358.27812 | D16: 258.10828 | E16: 203.72127 | F16: 173.03566 | G16: 149.53471 | H16: 129.67039 | I16: 117.13891 | J16: 110.01747 | K16: 104.27967 | L16: 100 | M16: 92.492013 | N16: 87.351399 | O16: 82.32376 | P16: 77.570406 | Q16: 72.965975 | R16: 69.330635 | S16: 66.425856 | T16: 62.861821 | U16: 60.130562 | V16: 59.123172 | W16: 56.648554 | X16: 54.878488 | Y16: 51.734291 | Z16: 48.545987 | AA16: 46.144402 | AB16: 44.233934 | AC16: 42.280656 | AD16: 40.464615 | AE16: 37.935583 | AF16: 36.241058 | AG16: 34.895881 | AH16: 33.361945 | AI16: 32.140602
A17: 2004 | B17: 419.74696 | C17: 387.36114 | D17: 279.06007 | E17: 220.25823 | F17: 187.08173 | G17: 161.6731 | H17: 140.19631 | I17: 126.6476 | J17: 118.94808 | K17: 112.74451 | L17: 108.11744 | M17: 100 | N17: 94.442099 | O17: 89.006344 | P17: 83.86714 | Q17: 78.888946 | R17: 74.95851 | S17: 71.817937 | T17: 67.964594 | U17: 65.011626 | V17: 63.922462 | W17: 61.246969 | X17: 59.333218 | Y17: 55.933792 | Z17: 52.48668 | AA17: 49.890147 | AB17: 47.824598 | AC17: 45.712764 | AD17: 43.749307 | AE17: 41.014982 | AF17: 39.182906 | AG17: 37.728534 | AH17: 36.070082 | AI17: 34.749597
... A39: 2026 | B39: 1207.9189 | C39: 1114.7212 | D39: 803.05989 | E39: 633.84399 | F39: 538.37095 | G39: 465.25173 | H39: 403.44731 | I39: 364.45775 | J39: 342.3006 | K39: 324.4484 | L39: 311.13294 | M39: 287.77312 | N39: 271.77898 | O39: 256.13633 | P39: 241.34709 | Q39: 227.02118 | R39: 215.71044 | S39: 206.67272 | T39: 195.58383 | U39: 187.08599 | V39: 183.95166 | W39: 176.25231 | X39: 170.74505 | Y39: 160.96242 | Z39: 151.04256 | AA39: 143.57043 | AB39: 137.62634 | AC39: 131.54905 | AD39: 125.89875 | AE39: 118.03009 | AF39: 112.75787 | AG39: 108.57258 | AH39: 103.8 | AI39: 100
A41: Fuente 1993-2024: INEGI. Sistema de Cuentas Nacionales de México.
B42: http://www.inegi.org.mx/sistemas/bie/
B43: Cuentas nacionales > Producto interno bruto trimestral, base 2018 > Índice acumulado de precios implícitos, 2020=100.0 Unidad de medida:Índice base 2020 = 100 Periodicidad: Trimestral
A45: Fuente 2025 y 2026: SHCP. Deflactor del PIB (variación anual, % promedio). Marco macroeconómico 2025-2026. Criterios Generales de Política Económica
B46: https://www.ppef.hacienda.gob.mx/work/models/PP3F2609/PPEF2026/Fiw326fP/paquete/politica_hacendaria/CGPE_2026.pdf
B47: 2025 | C47: 0.043
B48: 2026 | C48: 0.035
B50: 1993 | C50: 1994 | D50: 1995 | E50: 1996 | F50: 1997 | G50: 1998 | H50: 1999 | I50: 2000 | J50: 2001 | K50: 2002 | L50: 2003 | M50: 2004 | N50: 2005 | O50: 2006 | P50: 2007 | Q50: 2008 | R50: 2009 | S50: 2010 | T50: 2011 | U50: 2012 | V50: 2013 | W50: 2014 | X50: 2015 | Y50: 2016 | Z50: 2017 | AA50: 2018 | AB50: 2019 | AC50: 2020 | AD50: 2021 | AE50: 2022 | AF50: 2023 | AG50: 2024 | AH50: 2025 | AI50: 2026
A51: 1993=100 | B51: 100 | C51: 108.36063 | D51: 150.41455 | E51: 190.57038 | F51: 224.36555 | G51: 259.62696 | H51: 299.39943 | I51: 331.42907 | J51: 352.88251 | K51: 372.29925 | L51: 388.23241 | M51: 419.74696 | N51: 444.449 | O51: 471.59218 | P51: 500.49037 | Q51: 532.07322 | R51: 559.97239 | S51: 584.45978 | T51: 617.59651 | U51: 645.64907 | V51: 656.65018 | W51: 685.33508 | X51: 707.44007 | Y51: 750.43537 | Z51: 799.72092 | AA51: 841.3424 | AB51: 877.68006 | AC51: 918.22704 | AD51: 959.43682 | AE51: 1023.3991 | AF51: 1071.2502 | AG51: 1112.5451 | AH51: 1163.6984 | AI51: 1207.9189
A52: 1994=100 | B52: 92.284442 | C52: 100 | D52: 138.80923 | E52: 175.86682 | F52: 207.05449 | G52: 239.59529 | H52: 276.29909 | I52: 305.85747 | J52: 325.65565 | K52: 343.57428 | L52: 358.27812 | M52: 387.36114 | N52: 410.15727 | O52: 435.20621 | P52: 461.87475 | Q52: 491.0208 | R52: 516.76739 | S52: 539.36545 | T52: 569.94549 | U52: 595.83364 | V52: 605.98595 | W52: 632.45765 | X52: 652.85712 | Y52: 692.53509 | Z52: 738.01799 | AA52: 776.42813 | AB52: 809.96214 | AC52: 847.38069 | AD52: 885.41091 | AE52: 944.43815 | AF52: 988.59728 | AG52: 1026.706 | AH52: 1073.9126 | AI52: 1114.7212
A53: 1995=100 | B53: 66.482929 | C53: 72.041319 | D53: 100 | E53: 126.69677 | F53: 149.16479 | G53: 172.60761 | H53: 199.04951 | I53: 220.34376 | J53: 234.60663 | K53: 247.51544 | L53: 258.10828 | M53: 279.06007 | N53: 295.48271 | O53: 313.5283 | P53: 332.74066 | Q53: 353.73786 | R53: 372.28605 | S53: 388.56598 | T53: 410.59625 | U53: 429.24642 | V53: 436.56027 | W53: 455.63083 | X53: 470.32688 | Y53: 498.91141 | Z53: 531.67789 | AA53: 559.34907 | AB53: 583.50741 | AC53: 610.46423 | AD53: 637.8617 | AE53: 680.3857 | AF53: 712.19852 | AG53: 739.65258 | AH53: 773.66078 | AI53: 803.05989
A54: 1996=100 | B54: 52.474051 | C54: 56.86121 | D54: 78.928608 | E54: 100 | F54: 117.73369 | G54: 136.23678 | H54: 157.10701 | I54: 173.91426 | J54: 185.17174 | K54: 195.36049 | L54: 203.72127 | M54: 220.25823 | N54: 233.22039 | O54: 247.46352 | P54: 262.62757 | Q54: 279.20037 | R54: 293.84019 | S54: 306.68972 | T54: 324.07791 | U54: 338.79822 | V54: 344.57095 | W54: 359.62308 | X54: 371.22246 | Y54: 393.78383 | Z54: 419.64596 | AA54: 441.48643 | AB54: 460.55428 | AC54: 481.83092 | AD54: 503.45536 | AE54: 537.01896 | AF54: 562.12838 | AG54: 583.79749 | AH54: 610.63968 | AI54: 633.84399
A55: 1997=100 | B55: 44.570123 | C55: 48.296465 | D55: 67.03995 | E55: 84.937454 | F55: 100 | G55: 115.71606 | H55: 133.44269 | I55: 147.71834 | J55: 157.28017 | K55: 165.93423 | L55: 173.03566 | M55: 187.08173 | N55: 198.09146 | O55: 210.18921 | P55: 223.06917 | Q55: 237.14569 | R55: 249.58038 | S55: 260.49444 | T55: 275.26352 | U55: 287.76658 | V55: 292.66979 | W55: 305.45468 | X55: 315.30691 | Y55: 334.46996 | Z55: 356.4366 | AA55: 374.98734 | AB55: 391.18308 | AC55: 409.25492 | AD55: 427.62217 | AE55: 456.13024 | AF55: 477.45754 | AG55: 495.86272 | AH55: 518.6618 | AI55: 538.37095
A56: 1998=100 | B56: 38.516801 | C56: 41.737047 | D56: 57.934873 | E56: 73.401616 | F56: 86.418431 | G56: 100 | H56: 115.31908 | I56: 127.65588 | J56: 135.91905 | K56: 143.39776 | L56: 149.53471 | M56: 161.6731 | N56: 171.18753 | O56: 181.64222 | P56: 192.77288 | Q56: 204.93758 | R56: 215.68345 | S56: 225.11521 | T56: 237.87842 | U56: 248.68337 | V56: 252.92064 | W56: 263.96915 | X56: 272.48328 | Y56: 289.0437 | Z56: 308.02691 | AA56: 324.05818 | AB56: 338.05428 | AC56: 353.67168 | AD56: 369.54437 | AE56: 394.1806 | AF56: 412.61131 | AG56: 428.51679 | AH56: 448.21939 | AI56: 465.25173
A57: 1999=100 | B57: 33.400197 | C57: 36.192663 | D57: 50.238757 | E57: 63.650885 | F57: 74.938536 | G57: 86.715918 | H57: 100 | I57: 110.69796 | J57: 117.86345 | K57: 124.34868 | L57: 129.67039 | M57: 140.19631 | N57: 148.44684 | O57: 157.51272 | P57: 167.16477 | Q57: 177.71351 | R57: 187.03188 | S57: 195.21072 | T57: 206.27845 | U57: 215.64807 | V57: 219.32246 | W57: 228.90327 | X57: 236.28638 | Y57: 250.64689 | Z57: 267.10837 | AA57: 281.01002 | AB57: 293.14687 | AC57: 306.68964 | AD57: 320.45379 | AE57: 341.81732 | AF57: 357.79969 | AG57: 371.59226 | AH57: 388.67756 | AI57: 403.44731
A58: 2000=100 | B58: 30.172368 | C58: 32.694967 | D58: 45.383632 | E58: 57.499598 | F58: 67.696399 | G58: 78.335603 | H58: 90.335898 | I58: 100 | J58: 106.47301 | K58: 112.3315 | L58: 117.13891 | M58: 126.6476 | N58: 134.10079 | O58: 142.29053 | P58: 151.0098 | Q58: 160.53909 | R58: 168.95693 | S58: 176.34536 | T58: 186.34349 | U58: 194.80762 | V58: 198.12691 | W58: 206.78182 | X58: 213.45142 | Y58: 226.42412 | Z58: 241.29474 | AA58: 253.85293 | AB58: 264.81686 | AC58: 277.05084 | AD58: 289.48481 | AE58: 308.78375 | AF58: 323.22156 | AG58: 335.68121 | AH58: 351.11536 | AI58: 364.45775
A59: 2001=100 | B59: 28.338044 | C59: 30.707282 | D59: 42.624542 | E59: 54.00392 | F59: 63.580808 | G59: 73.573203 | H59: 84.843942 | I59: 93.920516 | J59: 100 | K59: 105.50232 | L59: 110.01747 | M59: 118.94808 | N59: 125.94815 | O59: 133.64 | P59: 141.82918 | Q59: 150.77914 | R59: 158.68522 | S59: 165.62447 | T59: 175.01477 | U59: 182.96432 | V59: 186.08182 | W59: 194.21056 | X59: 200.47468 | Y59: 212.6587 | Z59: 226.62527 | AA59: 238.41998 | AB59: 248.71736 | AC59: 260.20758 | AD59: 271.88563 | AE59: 290.01129 | AF59: 303.57136 | AG59: 315.27352 | AH59: 329.76936 | AI59: 342.3006
A60: 2002=100 | B60: 26.860114 | C60: 29.105788 | D60: 40.401519 | E60: 51.187422 | F60: 60.264841 | G60: 69.736097 | H60: 80.419026 | I60: 89.022225 | J60: 94.784642 | K60: 100 | L60: 104.27967 | M60: 112.74451 | N60: 119.3795 | O60: 126.6702 | P60: 134.43228 | Q60: 142.91547 | R60: 150.40922 | S60: 156.98656 | T60: 165.88712 | U60: 173.42207 | V60: 176.37698 | W60: 184.08178 | X60: 190.01921 | Y60: 201.56779 | Z60: 214.80595 | AA60: 225.98552 | AB60: 235.74586 | AC60: 246.63682 | AD60: 257.70582 | AE60: 274.88616 | AF60: 287.73902 | AG60: 298.83088 | AH60: 312.57071 | AI60: 324.4484
A61: 2003=100 | B61: 25.757767 | C61: 27.911278 | D61: 38.743429 | E61: 49.086675 | F61: 57.791555 | G61: 66.874107 | H61: 77.118606 | I61: 85.368728 | J61: 90.894653 | K61: 95.895972 | L61: 100 | M61: 108.11744 | N61: 114.48014 | O61: 121.47161 | P61: 128.91514 | Q61: 137.05018 | R61: 144.23638 | S61: 150.54379 | T61: 159.07907 | U61: 166.30478 | V61: 169.13842 | W61: 176.52701 | X61: 182.22076 | Y61: 193.29539 | Z61: 205.99025 | AA61: 216.71101 | AB61: 226.07078 | AC61: 236.51478 | AD61: 247.1295 | AE61: 263.60476 | AF61: 275.93013 | AG61: 286.56678 | AH61: 299.74272 | AI61: 311.13294
A62: 2004=100 | B62: 23.823877 | C62: 25.815703 | D62: 35.834578 | E62: 45.401254 | F62: 53.452573 | G62: 61.853208 | H62: 71.328552 | I62: 78.959255 | J62: 84.070295 | K62: 88.696115 | L62: 92.492013 | M62: 100 | N62: 105.88498 | O62: 112.35154 | P62: 119.23621 | Q62: 126.76047 | R62: 133.40713 | S62: 139.24098 | T62: 147.13543 | U62: 153.81864 | V62: 156.43953 | W62: 163.27339 | X62: 168.53965 | Y62: 178.7828 | Z62: 190.52453 | AA62: 200.44038 | AB62: 209.09742 | AC62: 218.75728 | AD62: 228.57505 | AE62: 243.81335 | AF62: 255.21334 | AG62: 265.05138 | AH62: 277.23807 | AI62: 287.77312
... A84: 2026=100 | B84: 8.2787013 | C84: 8.9708527 | D84: 12.452371 | E84: 15.776753 | F84: 18.574554 | G84: 21.493741 | H84: 24.786384 | I84: 27.438023 | J84: 29.214089 | K84: 30.821542 | L84: 32.140602 | M84: 34.749597 | N84: 36.794605 | O84: 39.041708 | P84: 41.434103 | Q84: 44.048753 | R84: 46.358441 | S84: 48.38568 | T84: 51.12897 | U84: 53.451358 | V84: 54.362107 | W84: 56.736844 | X84: 58.566851 | Y84: 62.126302 | Z84: 66.206506 | AA84: 69.652224 | AB84: 72.660511 | AC84: 76.017274 | AD84: 79.428908 | AE84: 84.724155 | AF84: 88.685606 | AG84: 92.104287 | AH84: 96.339114 | AI84: 100

Sheet Calculos deflactor
A1: Fórmula para deflactar: (valor corriente/deflactor)*100
B3: 2018=100 | D3: 1993=100 | E3: 1994=100 | F3: 1995=100 | G3: 1996=100 | H3: 1997=100 | I3: 1998=100 | J3: 1999=100 | K3: 2000=100 | L3: 2001=100 | M3: 2002=100 | N3: 2003=100 | O3: 2004=100 | P3: 2005=100 | Q3: 2006=100 | R3: 2007=100 | S3: 2008=100 | T3: 2009=100 | U3: 2010=100 | V3: 2011=100 | W3: 2012=100 | X3: 2013=100 | Y3: 2014=100 | Z3: 2015=100 | AA3: 2016=100 | AB3: 2017=100 | AC3: 2018=100 | AD3: 2019=100 | AE3: 2020=100 | AF3: 2021=100 | AG3: 2022=100 | AH3: 2023=100 | AI3: 2024=100 | AJ3: 2025=100 | AK3: 2026=100
A4: 1993 | B4: =VLOOKUP('Original INEGI Base 1993-2025'!D6,'Original INEGI Base 1993-2025'!$A$6:$B$160,2,0) -> 11.885767 | D4: =(($B4/$B$4)*100) -> 100 | E4: =(($B4/$B$5)*100) -> 92.284442 | F4: =(($B4/$B$6)*100) -> 66.482929 | G4: =(($B4/$B$7)*100) -> 52.474051 | H4: =(($B4/$B$8)*100) -> 44.570123 | I4: =(($B4/$B$9)*100) -> 38.516801 | J4: =(($B4/$B$10)*100) -> 33.400197 | K4: =(($B4/$B$11)*100) -> 30.172368 | L4: =(($B4/$B$12)*100) -> 28.338044 | M4: =(($B4/$B$13)*100) -> 26.860114 | N4: =(($B4/$B$14)*100) -> 25.757767 | O4: =(($B4/$B$15)*100) -> 23.823877 | P4: =(($B4/$B$16)*100) -> 22.49977 | Q4: =(($B4/$B$17)*100) -> 21.204762 | R4: =(($B4/$B$18)*100) -> 19.980404 | S4: =(($B4/$B$19)*100) -> 18.794406 | T4: =(($B4/$B$20)*100) -> 17.858023 | U4: =(($B4/$B$21)*100) -> 17.109817 | V4: =(($B4/$B$22)*100) -> 16.191801 | W4: =(($B4/$B$23)*100) -> 15.48829 | X4: =(($B4/$B$24)*100) -> 15.228809 | Y4: =(($B4/$B$25)*100) -> 14.591403 | Z4: =(($B4/$B$26)*100) -> 14.135473 | AA4: =(($B4/$B$27)*100) -> 13.325598 | AB4: =(($B4/$B$28)*100) -> 12.504362 | AC4: =(($B4/$B$29)*100) -> 11.885767 | AD4: =(($B4/$B$30)*100) -> 11.393673 | AE4: =(($B4/$B$31)*100) -> 10.890553 | AF4: =(($B4/$B$32)*100) -> 10.422781 | AG4: =(($B4/$B$33)*100) -> 9.7713589 | AH4: =(($B4/$B$34)*100) -> 9.3348873 | AI4: =(($B4/$B$35)*100) -> 8.9883996 | AJ4: =(($B4/$B$36)*100) -> 8.593292 | AK4: =(($B4/$B$37)*100) -> 8.2787013
A5: 1994 | B5: =VLOOKUP('Original INEGI Base 1993-2025'!D7,'Original INEGI Base 1993-2025'!$A$6:$B$160,2,0) -> 12.879492 | D5: =(($B5/$B$4)*100) -> 108.36063 | E5: =(($B5/$B$5)*100) -> 100 | F5: =(($B5/$B$6)*100) -> 72.041319 | G5: =(($B5/$B$7)*100) -> 56.86121 | H5: =(($B5/$B$8)*100) -> 48.296465 | I5: =(($B5/$B$9)*100) -> 41.737047 | J5: =(($B5/$B$10)*100) -> 36.192663 | K5: =(($B5/$B$11)*100) -> 32.694967 | L5: =(($B5/$B$12)*100) -> 30.707282 | M5: =(($B5/$B$13)*100) -> 29.105788 | N5: =(($B5/$B$14)*100) -> 27.911278 | O5: =(($B5/$B$15)*100) -> 25.815703 | P5: =(($B5/$B$16)*100) -> 24.380891 | Q5: =(($B5/$B$17)*100) -> 22.977613 | R5: =(($B5/$B$18)*100) -> 21.650892 | S5: =(($B5/$B$19)*100) -> 20.365736 | T5: =(($B5/$B$20)*100) -> 19.351066 | U5: =(($B5/$B$21)*100) -> 18.540305 | V5: =(($B5/$B$22)*100) -> 17.545537 | W5: =(($B5/$B$23)*100) -> 16.783208 | X5: =(($B5/$B$24)*100) -> 16.502033 | Y5: =(($B5/$B$25)*100) -> 15.811335 | Z5: =(($B5/$B$26)*100) -> 15.317287 | AA5: =(($B5/$B$27)*100) -> 14.439702 | AB5: =(($B5/$B$28)*100) -> 13.549805 | AC5: =(($B5/$B$29)*100) -> 12.879492 | AD5: =(($B5/$B$30)*100) -> 12.346256 | AE5: =(($B5/$B$31)*100) -> 11.801071 | AF5: =(($B5/$B$32)*100) -> 11.294191 | AG5: =(($B5/$B$33)*100) -> 10.588306 | AH5: =(($B5/$B$34)*100) -> 10.115342 | AI5: =(($B5/$B$35)*100) -> 9.7398861 | AJ5: =(($B5/$B$36)*100) -> 9.3117451 | AK5: =(($B5/$B$37)*100) -> 8.9708527
A6: 1995 | B6: =VLOOKUP('Original INEGI Base 1993-2025'!D8,'Original INEGI Base 1993-2025'!$A$6:$B$160,2,0) -> 17.877924 | D6: =(($B6/$B$4)*100) -> 150.41455 | E6: =(($B6/$B$5)*100) -> 138.80923 | F6: =(($B6/$B$6)*100) -> 100 | G6: =(($B6/$B$7)*100) -> 78.928608 | H6: =(($B6/$B$8)*100) -> 67.03995 | I6: =(($B6/$B$9)*100) -> 57.934873 | J6: =(($B6/$B$10)*100) -> 50.238757 | K6: =(($B6/$B$11)*100) -> 45.383632 | L6: =(($B6/$B$12)*100) -> 42.624542 | M6: =(($B6/$B$13)*100) -> 40.401519 | N6: =(($B6/$B$14)*100) -> 38.743429 | O6: =(($B6/$B$15)*100) -> 35.834578 | P6: =(($B6/$B$16)*100) -> 33.842928 | Q6: =(($B6/$B$17)*100) -> 31.895048 | R6: =(($B6/$B$18)*100) -> 30.053436 | S6: =(($B6/$B$19)*100) -> 28.269521 | T6: =(($B6/$B$20)*100) -> 26.861066 | U6: =(($B6/$B$21)*100) -> 25.735655 | V6: =(($B6/$B$22)*100) -> 24.354825 | W6: =(($B6/$B$23)*100) -> 23.296642 | X6: =(($B6/$B$24)*100) -> 22.906345 | Y6: =(($B6/$B$25)*100) -> 21.947593 | Z6: =(($B6/$B$26)*100) -> 21.261808 | AA6: =(($B6/$B$27)*100) -> 20.043638 | AB6: =(($B6/$B$28)*100) -> 18.80838 | AC6: =(($B6/$B$29)*100) -> 17.877924 | AD6: =(($B6/$B$30)*100) -> 17.137743 | AE6: =(($B6/$B$31)*100) -> 16.380976 | AF6: =(($B6/$B$32)*100) -> 15.67738 | AG6: =(($B6/$B$33)*100) -> 14.697546 | AH6: =(($B6/$B$34)*100) -> 14.041029 | AI6: =(($B6/$B$35)*100) -> 13.519861 | AJ6: =(($B6/$B$36)*100) -> 12.925562 | AK6: =(($B6/$B$37)*100) -> 12.452371
A7: 1996 | B7: =VLOOKUP('Original INEGI Base 1993-2025'!D9,'Original INEGI Base 1993-2025'!$A$6:$B$160,2,0) -> 22.650753 | D7: =(($B7/$B$4)*100) -> 190.57038 | E7: =(($B7/$B$5)*100) -> 175.86682 | F7: =(($B7/$B$6)*100) -> 126.69677 | G7: =(($B7/$B$7)*100) -> 100 | H7: =(($B7/$B$8)*100) -> 84.937454 | I7: =(($B7/$B$9)*100) -> 73.401616 | J7: =(($B7/$B$10)*100) -> 63.650885 | K7: =(($B7/$B$11)*100) -> 57.499598 | L7: =(($B7/$B$12)*100) -> 54.00392 | M7: =(($B7/$B$13)*100) -> 51.187422 | N7: =(($B7/$B$14)*100) -> 49.086675 | O7: =(($B7/$B$15)*100) -> 45.401254 | P7: =(($B7/$B$16)*100) -> 42.877897 | Q7: =(($B7/$B$17)*100) -> 40.409997 | R7: =(($B7/$B$18)*100) -> 38.076733 | S7: =(($B7/$B$19)*100) -> 35.816571 | T7: =(($B7/$B$20)*100) -> 34.032104 | U7: =(($B7/$B$21)*100) -> 32.606244 | V7: =(($B7/$B$22)*100) -> 30.856778 | W7: =(($B7/$B$23)*100) -> 29.516094 | X7: =(($B7/$B$24)*100) -> 29.0216 | Y7: =(($B7/$B$25)*100) -> 27.806892 | Z7: =(($B7/$B$26)*100) -> 26.938025 | AA7: =(($B7/$B$27)*100) -> 25.394643 | AB7: =(($B7/$B$28)*100) -> 23.829611 | AC7: =(($B7/$B$29)*100) -> 22.650753 | AD7: =(($B7/$B$30)*100) -> 21.712967 | AE7: =(($B7/$B$31)*100) -> 20.754168 | AF7: =(($B7/$B$32)*100) -> 19.862734 | AG7: =(($B7/$B$33)*100) -> 18.621316 | AH7: =(($B7/$B$34)*100) -> 17.789531 | AI7: =(($B7/$B$35)*100) -> 17.129228 | AJ7: =(($B7/$B$36)*100) -> 16.37627 | AK7: =(($B7/$B$37)*100) -> 15.776753
A8: 1997 | B8: =VLOOKUP('Original INEGI Base 1993-2025'!D10,'Original INEGI Base 1993-2025'!$A$6:$B$160,2,0) -> 26.667567 | D8: =(($B8/$B$4)*100) -> 224.36555 | E8: =(($B8/$B$5)*100) -> 207.05449 | F8: =(($B8/$B$6)*100) -> 149.16479 | G8: =(($B8/$B$7)*100) -> 117.73369 | H8: =(($B8/$B$8)*100) -> 100 | I8: =(($B8/$B$9)*100) -> 86.418431 | J8: =(($B8/$B$10)*100) -> 74.938536 | K8: =(($B8/$B$11)*100) -> 67.696399 | L8: =(($B8/$B$12)*100) -> 63.580808 | M8: =(($B8/$B$13)*100) -> 60.264841 | N8: =(($B8/$B$14)*100) -> 57.791555 | O8: =(($B8/$B$15)*100) -> 53.452573 | P8: =(($B8/$B$16)*100) -> 50.481731 | Q8: =(($B8/$B$17)*100) -> 47.576181 | R8: =(($B8/$B$18)*100) -> 44.829144 | S8: =(($B8/$B$19)*100) -> 42.168171 | T8: =(($B8/$B$20)*100) -> 40.067252 | U8: =(($B8/$B$21)*100) -> 38.388535 | V8: =(($B8/$B$22)*100) -> 36.328824 | W8: =(($B8/$B$23)*100) -> 34.750387 | X8: =(($B8/$B$24)*100) -> 34.1682 | Y8: =(($B8/$B$25)*100) -> 32.73808 | Z8: =(($B8/$B$26)*100) -> 31.715131 | AA8: =(($B8/$B$27)*100) -> 29.898051 | AB8: =(($B8/$B$28)*100) -> 28.055481 | AC8: =(($B8/$B$29)*100) -> 26.667567 | AD8: =(($B8/$B$30)*100) -> 25.563478 | AE8: =(($B8/$B$31)*100) -> 24.434648 | AF8: =(($B8/$B$32)*100) -> 23.38513 | AG8: =(($B8/$B$33)*100) -> 21.923563 | AH8: =(($B8/$B$34)*100) -> 20.944271 | AI8: =(($B8/$B$35)*100) -> 20.166872 | AJ8: =(($B8/$B$36)*100) -> 19.280387 | AK8: =(($B8/$B$37)*100) -> 18.574554
A9: 1998 | B9: =VLOOKUP('Original INEGI Base 1993-2025'!D11,'Original INEGI Base 1993-2025'!$A$6:$B$160,2,0) -> 30.858657 | D9: =(($B9/$B$4)*100) -> 259.62696 | E9: =(($B9/$B$5)*100) -> 239.59529 | F9: =(($B9/$B$6)*100) -> 172.60761 | G9: =(($B9/$B$7)*100) -> 136.23678 | H9: =(($B9/$B$8)*100) -> 115.71606 | I9: =(($B9/$B$9)*100) -> 100 | J9: =(($B9/$B$10)*100) -> 86.715918 | K9: =(($B9/$B$11)*100) -> 78.335603 | L9: =(($B9/$B$12)*100) -> 73.573203 | M9: =(($B9/$B$13)*100) -> 69.736097 | N9: =(($B9/$B$14)*100) -> 66.874107 | O9: =(($B9/$B$15)*100) -> 61.853208 | P9: =(($B9/$B$16)*100) -> 58.415468 | Q9: =(($B9/$B$17)*100) -> 55.053279 | R9: =(($B9/$B$18)*100) -> 51.874517 | S9: =(($B9/$B$19)*100) -> 48.795344 | T9: =(($B9/$B$20)*100) -> 46.364243 | U9: =(($B9/$B$21)*100) -> 44.421698 | V9: =(($B9/$B$22)*100) -> 42.038282 | W9: =(($B9/$B$23)*100) -> 40.211777 | X9: =(($B9/$B$24)*100) -> 39.538094 | Y9: =(($B9/$B$25)*100) -> 37.883215 | Z9: =(($B9/$B$26)*100) -> 36.699499 | AA9: =(($B9/$B$27)*100) -> 34.596845 | AB9: =(($B9/$B$28)*100) -> 32.464696 | AC9: =(($B9/$B$29)*100) -> 30.858657 | AD9: =(($B9/$B$30)*100) -> 29.581048 | AE9: =(($B9/$B$31)*100) -> 28.274811 | AF9: =(($B9/$B$32)*100) -> 27.06035 | AG9: =(($B9/$B$33)*100) -> 25.369082 | AH9: =(($B9/$B$34)*100) -> 24.235884 | AI9: =(($B9/$B$35)*100) -> 23.336309 | AJ9: =(($B9/$B$36)*100) -> 22.310503 | AK9: =(($B9/$B$37)*100) -> 21.493741
A10: 1999 | B10: =VLOOKUP('Original INEGI Base 1993-2025'!D12,'Original INEGI Base 1993-2025'!$A$6:$B$160,2,0) -> 35.585919 | D10: =(($B10/$B$4)*100) -> 299.39943 | E10: =(($B10/$B$5)*100) -> 276.29909 | F10: =(($B10/$B$6)*100) -> 199.04951 | G10: =(($B10/$B$7)*100) -> 157.10701 | H10: =(($B10/$B$8)*100) -> 133.44269 | I10: =(($B10/$B$9)*100) -> 115.31908 | J10: =(($B10/$B$10)*100) -> 100 | K10: =(($B10/$B$11)*100) -> 90.335898 | L10: =(($B10/$B$12)*100) -> 84.843942 | M10: =(($B10/$B$13)*100) -> 80.419026 | N10: =(($B10/$B$14)*100) -> 77.118606 | O10: =(($B10/$B$15)*100) -> 71.328552 | P10: =(($B10/$B$16)*100) -> 67.364181 | Q10: =(($B10/$B$17)*100) -> 63.486936 | R10: =(($B10/$B$18)*100) -> 59.821216 | S10: =(($B10/$B$19)*100) -> 56.270343 | T10: =(($B10/$B$20)*100) -> 53.46682 | U10: =(($B10/$B$21)*100) -> 51.226695 | V10: =(($B10/$B$22)*100) -> 48.47816 | W10: =(($B10/$B$23)*100) -> 46.371851 | X10: =(($B10/$B$24)*100) -> 45.594966 | Y10: =(($B10/$B$25)*100) -> 43.686576 | Z10: =(($B10/$B$26)*100) -> 42.321525 | AA10: =(($B10/$B$27)*100) -> 39.896764 | AB10: =(($B10/$B$28)*100) -> 37.437989 | AC10: =(($B10/$B$29)*100) -> 35.585919 | AD10: =(($B10/$B$30)*100) -> 34.112593 | AE10: =(($B10/$B$31)*100) -> 32.606253 | AF10: =(($B10/$B$32)*100) -> 31.205747 | AG10: =(($B10/$B$33)*100) -> 29.255393 | AH10: =(($B10/$B$34)*100) -> 27.948599 | AI10: =(($B10/$B$35)*100) -> 26.911217 | AJ10: =(($B10/$B$36)*100) -> 25.728267 | AK10: =(($B10/$B$37)*100) -> 24.786384
A11: 2000 | B11: =VLOOKUP('Original INEGI Base 1993-2025'!D13,'Original INEGI Base 1993-2025'!$A$6:$B$160,2,0) -> 39.392889 | D11: =(($B11/$B$4)*100) -> 331.42907 | E11: =(($B11/$B$5)*100) -> 305.85747 | F11: =(($B11/$B$6)*100) -> 220.34376 | G11: =(($B11/$B$7)*100) -> 173.91426 | H11: =(($B11/$B$8)*100) -> 147.71834 | I11: =(($B11/$B$9)*100) -> 127.65588 | J11: =(($B11/$B$10)*100) -> 110.69796 | K11: =(($B11/$B$11)*100) -> 100 | L11: =(($B11/$B$12)*100) -> 93.920516 | M11: =(($B11/$B$13)*100) -> 89.022225 | N11: =(($B11/$B$14)*100) -> 85.368728 | O11: =(($B11/$B$15)*100) -> 78.959255 | P11: =(($B11/$B$16)*100) -> 74.570778 | Q11: =(($B11/$B$17)*100) -> 70.278746 | R11: =(($B11/$B$18)*100) -> 66.220869 | S11: =(($B11/$B$19)*100) -> 62.290124 | T11: =(($B11/$B$20)*100) -> 59.186681 | U11: =(($B11/$B$21)*100) -> 56.706908 | V11: =(($B11/$B$22)*100) -> 53.664337 | W11: =(($B11/$B$23)*100) -> 51.332695 | X11: =(($B11/$B$24)*100) -> 50.4727 | Y11: =(($B11/$B$25)*100) -> 48.36015 | Z11: =(($B11/$B$26)*100) -> 46.849067 | AA11: =(($B11/$B$27)*100) -> 44.164906 | AB11: =(($B11/$B$28)*100) -> 41.443091 | AC11: =(($B11/$B$29)*100) -> 39.392889 | AD11: =(($B11/$B$30)*100) -> 37.761946 | AE11: =(($B11/$B$31)*100) -> 36.094458 | AF11: =(($B11/$B$32)*100) -> 34.544127 | AG11: =(($B11/$B$33)*100) -> 32.385124 | AH11: =(($B11/$B$34)*100) -> 30.93853 | AI11: =(($B11/$B$35)*100) -> 29.790169 | AJ11: =(($B11/$B$36)*100) -> 28.480668 | AK11: =(($B11/$B$37)*100) -> 27.438023
A12: 2001 | B12: =VLOOKUP('Original INEGI Base 1993-2025'!D14,'Original INEGI Base 1993-2025'!$A$6:$B$160,2,0) -> 41.942794 | D12: =(($B12/$B$4)*100) -> 352.88251 | E12: =(($B12/$B$5)*100) -> 325.65565 | F12: =(($B12/$B$6)*100) -> 234.60663 | G12: =(($B12/$B$7)*100) -> 185.17174 | H12: =(($B12/$B$8)*100) -> 157.28017 | I12: =(($B12/$B$9)*100) -> 135.91905 | J12: =(($B12/$B$10)*100) -> 117.86345 | K12: =(($B12/$B$11)*100) -> 106.47301 | L12: =(($B12/$B$12)*100) -> 100 | M12: =(($B12/$B$13)*100) -> 94.784642 | N12: =(($B12/$B$14)*100) -> 90.894653 | O12: =(($B12/$B$15)*100) -> 84.070295 | P12: =(($B12/$B$16)*100) -> 79.397751 | Q12: =(($B12/$B$17)*100) -> 74.827896 | R12: =(($B12/$B$18)*100) -> 70.507352 | S12: =(($B12/$B$19)*100) -> 66.32217 | T12: =(($B12/$B$20)*100) -> 63.01784 | U12: =(($B12/$B$21)*100) -> 60.377551 | V12: =(($B12/$B$22)*100) -> 57.138034 | W12: =(($B12/$B$23)*100) -> 54.655466 | X12: =(($B12/$B$24)*100) -> 53.739802 | Y12: =(($B12/$B$25)*100) -> 51.490507 | Z12: =(($B12/$B$26)*100) -> 49.881611 | AA12: =(($B12/$B$27)*100) -> 47.023704 | AB12: =(($B12/$B$28)*100) -> 44.125706 | AC12: =(($B12/$B$29)*100) -> 41.942794 | AD12: =(($B12/$B$30)*100) -> 40.20628 | AE12: =(($B12/$B$31)*100) -> 38.430856 | AF12: =(($B12/$B$32)*100) -> 36.780172 | AG12: =(($B12/$B$33)*100) -> 34.481416 | AH12: =(($B12/$B$34)*100) -> 32.941184 | AI12: =(($B12/$B$35)*100) -> 31.71849 | AJ12: =(($B12/$B$36)*100) -> 30.324224 | AK12: =(($B12/$B$37)*100) -> 29.214089
A13: 2002 | B13: =VLOOKUP('Original INEGI Base 1993-2025'!D15,'Original INEGI Base 1993-2025'!$A$6:$B$160,2,0) -> 44.250622 | D13: =(($B13/$B$4)*100) -> 372.29925 | E13: =(($B13/$B$5)*100) -> 343.57428 | F13: =(($B13/$B$6)*100) -> 247.51544 | G13: =(($B13/$B$7)*100) -> 195.36049 | H13: =(($B13/$B$8)*100) -> 165.93423 | I13: =(($B13/$B$9)*100) -> 143.39776 | J13: =(($B13/$B$10)*100) -> 124.34868 | K13: =(($B13/$B$11)*100) -> 112.3315 | L13: =(($B13/$B$12)*100) -> 105.50232 | M13: =(($B13/$B$13)*100) -> 100 | N13: =(($B13/$B$14)*100) -> 95.895972 | O13: =(($B13/$B$15)*100) -> 88.696115 | P13: =(($B13/$B$16)*100) -> 83.766472 | Q13: =(($B13/$B$17)*100) -> 78.945169 | R13: =(($B13/$B$18)*100) -> 74.386895 | S13: =(($B13/$B$19)*100) -> 69.97143 | T13: =(($B13/$B$20)*100) -> 66.485286 | U13: =(($B13/$B$21)*100) -> 63.69972 | V13: =(($B13/$B$22)*100) -> 60.281954 | W13: =(($B13/$B$23)*100) -> 57.662786 | X13: =(($B13/$B$24)*100) -> 56.69674 | Y13: =(($B13/$B$25)*100) -> 54.323682 | Z13: =(($B13/$B$26)*100) -> 52.626259 | AA13: =(($B13/$B$27)*100) -> 49.611101 | AB13: =(($B13/$B$28)*100) -> 46.553646 | AC13: =(($B13/$B$29)*100) -> 44.250622 | AD13: =(($B13/$B$30)*100) -> 42.41856 | AE13: =(($B13/$B$31)*100) -> 40.545446 | AF13: =(($B13/$B$32)*100) -> 38.803936 | AG13: =(($B13/$B$33)*100) -> 36.378696 | AH13: =(($B13/$B$34)*100) -> 34.753715 | AI13: =(($B13/$B$35)*100) -> 33.463744 | AJ13: =(($B13/$B$36)*100) -> 31.992761 | AK13: =(($B13/$B$37)*100) -> 30.821542
A14: 2003 | B14: =VLOOKUP('Original INEGI Base 1993-2025'!D16,'Original INEGI Base 1993-2025'!$A$6:$B$160,2,0) -> 46.144402 | D14: =(($B14/$B$4)*100) -> 388.23241 | E14: =(($B14/$B$5)*100) -> 358.27812 | F14: =(($B14/$B$6)*100) -> 258.10828 | G14: =(($B14/$B$7)*100) -> 203.72127 | H14: =(($B14/$B$8)*100) -> 173.03566 | I14: =(($B14/$B$9)*100) -> 149.53471 | J14: =(($B14/$B$10)*100) -> 129.67039 | K14: =(($B14/$B$11)*100) -> 117.13891 | L14: =(($B14/$B$12)*100) -> 110.01747 | M14: =(($B14/$B$13)*100) -> 104.27967 | N14: =(($B14/$B$14)*100) -> 100 | O14: =(($B14/$B$15)*100) -> 92.492013 | P14: =(($B14/$B$16)*100) -> 87.351399 | Q14: =(($B14/$B$17)*100) -> 82.32376 | R14: =(($B14/$B$18)*100) -> 77.570406 | S14: =(($B14/$B$19)*100) -> 72.965975 | T14: =(($B14/$B$20)*100) -> 69.330635 | U14: =(($B14/$B$21)*100) -> 66.425856 | V14: =(($B14/$B$22)*100) -> 62.861821 | W14: =(($B14/$B$23)*100) -> 60.130562 | X14: =(($B14/$B$24)*100) -> 59.123172 | Y14: =(($B14/$B$25)*100) -> 56.648554 | Z14: =(($B14/$B$26)*100) -> 54.878488 | AA14: =(($B14/$B$27)*100) -> 51.734291 | AB14: =(($B14/$B$28)*100) -> 48.545987 | AC14: =(($B14/$B$29)*100) -> 46.144402 | AD14: =(($B14/$B$30)*100) -> 44.233934 | AE14: =(($B14/$B$31)*100) -> 42.280656 | AF14: =(($B14/$B$32)*100) -> 40.464615 | AG14: =(($B14/$B$33)*100) -> 37.935583 | AH14: =(($B14/$B$34)*100) -> 36.241058 | AI14: =(($B14/$B$35)*100) -> 34.895881 | AJ14: =(($B14/$B$36)*100) -> 33.361945 | AK14: =(($B14/$B$37)*100) -> 32.140602
A15: 2004 | B15: =VLOOKUP('Original INEGI Base 1993-2025'!D17,'Original INEGI Base 1993-2025'!$A$6:$B$160,2,0) -> 49.890147 | D15: =(($B15/$B$4)*100) -> 419.74696 | E15: =(($B15/$B$5)*100) -> 387.36114 | F15: =(($B15/$B$6)*100) -> 279.06007 | G15: =(($B15/$B$7)*100) -> 220.25823 | H15: =(($B15/$B$8)*100) -> 187.08173 | I15: =(($B15/$B$9)*100) -> 161.6731 | J15: =(($B15/$B$10)*100) -> 140.19631 | K15: =(($B15/$B$11)*100) -> 126.6476 | L15: =(($B15/$B$12)*100) -> 118.94808 | M15: =(($B15/$B$13)*100) -> 112.74451 | N15: =(($B15/$B$14)*100) -> 108.11744 | O15: =(($B15/$B$15)*100) -> 100 | P15: =(($B15/$B$16)*100) -> 94.442099 | Q15: =(($B15/$B$17)*100) -> 89.006344 | R15: =(($B15/$B$18)*100) -> 83.86714 | S15: =(($B15/$B$19)*100) -> 78.888946 | T15: =(($B15/$B$20)*100) -> 74.95851 | U15: =(($B15/$B$21)*100) -> 71.817937 | V15: =(($B15/$B$22)*100) -> 67.964594 | W15: =(($B15/$B$23)*100) -> 65.011626 | X15: =(($B15/$B$24)*100) -> 63.922462 | Y15: =(($B15/$B$25)*100) -> 61.246969 | Z15: =(($B15/$B$26)*100) -> 59.333218 | AA15: =(($B15/$B$27)*100) -> 55.933792 | AB15: =(($B15/$B$28)*100) -> 52.48668 | AC15: =(($B15/$B$29)*100) -> 49.890147 | AD15: =(($B15/$B$30)*100) -> 47.824598 | AE15: =(($B15/$B$31)*100) -> 45.712764 | AF15: =(($B15/$B$32)*100) -> 43.749307 | AG15: =(($B15/$B$33)*100) -> 41.014982 | AH15: =(($B15/$B$34)*100) -> 39.182906 | AI15: =(($B15/$B$35)*100) -> 37.728534 | AJ15: =(($B15/$B$36)*100) -> 36.070082 | AK15: =(($B15/$B$37)*100) -> 34.749597
... A36: 2025 | B36: =VLOOKUP('Original INEGI Base 1993-2025'!D38,'Original INEGI Base 1993-2025'!$A$6:$B$160,2,0) -> 138.31448 | D36: =(($B36/$B$4)*100) -> 1163.6984 | E36: =(($B36/$B$5)*100) -> 1073.9126 | F36: =(($B36/$B$6)*100) -> 773.66078 | G36: =(($B36/$B$7)*100) -> 610.63968 | H36: =(($B36/$B$8)*100) -> 518.6618 | I36: =(($B36/$B$9)*100) -> 448.21939 | J36: =(($B36/$B$10)*100) -> 388.67756 | K36: =(($B36/$B$11)*100) -> 351.11536 | L36: =(($B36/$B$12)*100) -> 329.76936 | M36: =(($B36/$B$13)*100) -> 312.57071 | N36: =(($B36/$B$14)*100) -> 299.74272 | O36: =(($B36/$B$15)*100) -> 277.23807 | P36: =(($B36/$B$16)*100) -> 261.82946 | Q36: =(($B36/$B$17)*100) -> 246.75947 | R36: =(($B36/$B$18)*100) -> 232.51164 | S36: =(($B36/$B$19)*100) -> 218.7102 | T36: =(($B36/$B$20)*100) -> 207.81353 | U36: =(($B36/$B$21)*100) -> 199.10667 | V36: =(($B36/$B$22)*100) -> 188.42373 | W36: =(($B36/$B$23)*100) -> 180.23698 | X36: =(($B36/$B$24)*100) -> 177.2174 | Y36: =(($B36/$B$25)*100) -> 169.79992 | Z36: =(($B36/$B$26)*100) -> 164.49427 | AA36: =(($B36/$B$27)*100) -> 155.06977 | AB36: =(($B36/$B$28)*100) -> 145.51306 | AC36: =(($B36/$B$29)*100) -> 138.31448 | AD36: =(($B36/$B$30)*100) -> 132.58799 | AE36: =(($B36/$B$31)*100) -> 126.73319 | AF36: =(($B36/$B$32)*100) -> 121.28974 | AG36: =(($B36/$B$33)*100) -> 113.70915 | AH36: =(($B36/$B$34)*100) -> 108.62993 | AI36: =(($B36/$B$35)*100) -> 104.59786 | AJ36: =(($B36/$B$36)*100) -> 100 | AK36: =(($B36/$B$37)*100) -> 96.339114
A37: 2026 | B37: =B36*(1+C46) -> 143.57043 | D37: =(($B37/$B$4)*100) -> 1207.9189 | E37: =(($B37/$B$5)*100) -> 1114.7212 | F37: =(($B37/$B$6)*100) -> 803.05989 | G37: =(($B37/$B$7)*100) -> 633.84399 | H37: =(($B37/$B$8)*100) -> 538.37095 | I37: =(($B37/$B$9)*100) -> 465.25173 | J37: =(($B37/$B$10)*100) -> 403.44731 | K37: =(($B37/$B$11)*100) -> 364.45775 | L37: =(($B37/$B$12)*100) -> 342.3006 | M37: =(($B37/$B$13)*100) -> 324.4484 | N37: =(($B37/$B$14)*100) -> 311.13294 | O37: =(($B37/$B$15)*100) -> 287.77312 | P37: =(($B37/$B$16)*100) -> 271.77898 | Q37: =(($B37/$B$17)*100) -> 256.13633 | R37: =(($B37/$B$18)*100) -> 241.34709 | S37: =(($B37/$B$19)*100) -> 227.02118 | T37: =(($B37/$B$20)*100) -> 215.71044 | U37: =(($B37/$B$21)*100) -> 206.67272 | V37: =(($B37/$B$22)*100) -> 195.58383 | W37: =(($B37/$B$23)*100) -> 187.08599 | X37: =(($B37/$B$24)*100) -> 183.95166 | Y37: =(($B37/$B$25)*100) -> 176.25231 | Z37: =(($B37/$B$26)*100) -> 170.74505 | AA37: =(($B37/$B$27)*100) -> 160.96242 | AB37: =(($B37/$B$28)*100) -> 151.04256 | AC37: =(($B37/$B$29)*100) -> 143.57043 | AD37: =(($B37/$B$30)*100) -> 137.62634 | AE37: =(($B37/$B$31)*100) -> 131.54905 | AF37: =(($B37/$B$32)*100) -> 125.89875 | AG37: =(($B37/$B$33)*100) -> 118.03009 | AH37: =(($B37/$B$34)*100) -> 112.75787 | AI37: =(($B37/$B$35)*100) -> 108.57258 | AJ37: =(($B37/$B$36)*100) -> 103.8 | AK37: =(($B37/$B$37)*100) -> 100
A40: Fuente 1993-2025: INEGI. Sistema de Cuentas Nacionales de México.
B41: http://www.inegi.org.mx/sistemas/bie/
B42: Cuentas nacionales > Producto interno bruto trimestral, base 2018 > Índice acumulado de precios implícitos, 2018 = 100.0 Unidad de medida:Índice base 2018 = 100 Periodicidad: Trimestral
A44: Fuente 2026: SHCP. Deflactor del PIB (variación anual, % promedio). Marco macroeconómico 2023-2030. Criterios Generales de Política Económica
B45: https://www.finanzaspublicas.hacienda.gob.mx/en/Finanzas_Publicas/Paquete_Economico_y_Presupuesto
B46: 2026 | C46: 0.038
B48: 1993 | C48: 1994 | D48: 1995 | E48: 1996 | F48: 1997 | G48: 1998 | H48: 1999 | I48: 2000 | J48: 2001 | K48: 2002 | L48: 2003 | M48: 2004 | N48: 2005 | O48: 2006 | P48: 2007 | Q48: 2008 | R48: 2009 | S48: 2010 | T48: 2011 | U48: 2012 | V48: 2013 | W48: 2014 | X48: 2015 | Y48: 2016 | Z48: 2017 | AA48: 2018 | AB48: 2019 | AC48: 2020 | AD48: 2021 | AE48: 2022 | AF48: 2023 | AG48: 2024 | AH48: 2025 | AI48: 2026
A49: 1993=100 | B49: =D4 -> 100 | C49: =D5 -> 108.36063 | D49: =D6 -> 150.41455 | E49: =D7 -> 190.57038 | F49: =D8 -> 224.36555 | G49: =D9 -> 259.62696 | H49: =D10 -> 299.39943 | I49: =D11 -> 331.42907 | J49: =D12 -> 352.88251 | K49: =D13 -> 372.29925 | L49: =D14 -> 388.23241 | M49: =D15 -> 419.74696 | N49: =D16 -> 444.449 | O49: =D17 -> 471.59218 | P49: =D18 -> 500.49037 | Q49: =D19 -> 532.07322 | R49: =D20 -> 559.97239 | S49: =D21 -> 584.45978 | T49: =D22 -> 617.59651 | U49: =D23 -> 645.64907 | V49: =D24 -> 656.65018 | W49: =D25 -> 685.33508 | X49: =D26 -> 707.44007 | Y49: =D27 -> 750.43537 | Z49: =D28 -> 799.72092 | AA49: =D29 -> 841.3424 | AB49: =D30 -> 877.68006 | AC49: =D31 -> 918.22704 | AD49: =D32 -> 959.43682 | AE49: =D33 -> 1023.3991 | AF49: =D34 -> 1071.2502 | AG49: =D35 -> 1112.5451 | AH49: =D36 -> 1163.6984 | AI49: =D37 -> 1207.9189
A50: 1994=100 | B50: =E4 -> 92.284442 | C50: =E5 -> 100 | D50: =E6 -> 138.80923 | E50: =E7 -> 175.86682 | F50: =E8 -> 207.05449 | G50: =E9 -> 239.59529 | H50: =E10 -> 276.29909 | I50: =E11 -> 305.85747 | J50: =E12 -> 325.65565 | K50: =E13 -> 343.57428 | L50: =E14 -> 358.27812 | M50: =E15 -> 387.36114 | N50: =E16 -> 410.15727 | O50: =E17 -> 435.20621 | P50: =E18 -> 461.87475 | Q50: =E19 -> 491.0208 | R50: =E20 -> 516.76739 | S50: =E21 -> 539.36545 | T50: =E22 -> 569.94549 | U50: =E23 -> 595.83364 | V50: =E24 -> 605.98595 | W50: =E25 -> 632.45765 | X50: =E26 -> 652.85712 | Y50: =E27 -> 692.53509 | Z50: =E28 -> 738.01799 | AA50: =E29 -> 776.42813 | AB50: =E30 -> 809.96214 | AC50: =E31 -> 847.38069 | AD50: =E32 -> 885.41091 | AE50: =E33 -> 944.43815 | AF50: =E34 -> 988.59728 | AG50: =E35 -> 1026.706 | AH50: =E36 -> 1073.9126 | AI50: =E37 -> 1114.7212
A51: 1995=100 | B51: =F4 -> 66.482929 | C51: =F5 -> 72.041319 | D51: =F6 -> 100 | E51: =F7 -> 126.69677 | F51: =F8 -> 149.16479 | G51: =F9 -> 172.60761 | H51: =F10 -> 199.04951 | I51: =F11 -> 220.34376 | J51: =F12 -> 234.60663 | K51: =F13 -> 247.51544 | L51: =F14 -> 258.10828 | M51: =F15 -> 279.06007 | N51: =F16 -> 295.48271 | O51: =F17 -> 313.5283 | P51: =F18 -> 332.74066 | Q51: =F19 -> 353.73786 | R51: =F20 -> 372.28605 | S51: =F21 -> 388.56598 | T51: =F22 -> 410.59625 | U51: =F23 -> 429.24642 | V51: =F24 -> 436.56027 | W51: =F25 -> 455.63083 | X51: =F26 -> 470.32688 | Y51: =F27 -> 498.91141 | Z51: =F28 -> 531.67789 | AA51: =F29 -> 559.34907 | AB51: =F30 -> 583.50741 | AC51: =F31 -> 610.46423 | AD51: =F32 -> 637.8617 | AE51: =F33 -> 680.3857 | AF51: =F34 -> 712.19852 | AG51: =F35 -> 739.65258 | AH51: =F36 -> 773.66078 | AI51: =F37 -> 803.05989
A52: 1996=100 | B52: =G4 -> 52.474051 | C52: =G5 -> 56.86121 | D52: =G6 -> 78.928608 | E52: =G7 -> 100 | F52: =G8 -> 117.73369 | G52: =G9 -> 136.23678 | H52: =G10 -> 157.10701 | I52: =G11 -> 173.91426 | J52: =G12 -> 185.17174 | K52: =G13 -> 195.36049 | L52: =G14 -> 203.72127 | M52: =G15 -> 220.25823 | N52: =G16 -> 233.22039 | O52: =G17 -> 247.46352 | P52: =G18 -> 262.62757 | Q52: =G19 -> 279.20037 | R52: =G20 -> 293.84019 | S52: =G21 -> 306.68972 | T52: =G22 -> 324.07791 | U52: =G23 -> 338.79822 | V52: =G24 -> 344.57095 | W52: =G25 -> 359.62308 | X52: =G26 -> 371.22246 | Y52: =G27 -> 393.78383 | Z52: =G28 -> 419.64596 | AA52: =G29 -> 441.48643 | AB52: =G30 -> 460.55428 | AC52: =G31 -> 481.83092 | AD52: =G32 -> 503.45536 | AE52: =G33 -> 537.01896 | AF52: =G34 -> 562.12838 | AG52: =G35 -> 583.79749 | AH52: =G36 -> 610.63968 | AI52: =G37 -> 633.84399
A53: 1997=100 | B53: =H4 -> 44.570123 | C53: =H5 -> 48.296465 | D53: =H6 -> 67.03995 | E53: =H7 -> 84.937454 | F53: =H8 -> 100 | G53: =H9 -> 115.71606 | H53: =H10 -> 133.44269 | I53: =H11 -> 147.71834 | J53: =H12 -> 157.28017 | K53: =H13 -> 165.93423 | L53: =H14 -> 173.03566 | M53: =H15 -> 187.08173 | N53: =H16 -> 198.09146 | O53: =H17 -> 210.18921 | P53: =H18 -> 223.06917 | Q53: =H19 -> 237.14569 | R53: =H20 -> 249.58038 | S53: =H21 -> 260.49444 | T53: =H22 -> 275.26352 | U53: =H23 -> 287.76658 | V53: =H24 -> 292.66979 | W53: =H25 -> 305.45468 | X53: =H26 -> 315.30691 | Y53: =H27 -> 334.46996 | Z53: =H28 -> 356.4366 | AA53: =H29 -> 374.98734 | AB53: =H30 -> 391.18308 | AC53: =H31 -> 409.25492 | AD53: =H32 -> 427.62217 | AE53: =H33 -> 456.13024 | AF53: =H34 -> 477.45754 | AG53: =H35 -> 495.86272 | AH53: =H36 -> 518.6618 | AI53: =H37 -> 538.37095
A54: 1998=100 | B54: =I4 -> 38.516801 | C54: =I5 -> 41.737047 | D54: =I6 -> 57.934873 | E54: =I7 -> 73.401616 | F54: =I8 -> 86.418431 | G54: =I9 -> 100 | H54: =I10 -> 115.31908 | I54: =I11 -> 127.65588 | J54: =I12 -> 135.91905 | K54: =I13 -> 143.39776 | L54: =I14 -> 149.53471 | M54: =I15 -> 161.6731 | N54: =I16 -> 171.18753 | O54: =I17 -> 181.64222 | P54: =I18 -> 192.77288 | Q54: =I19 -> 204.93758 | R54: =I20 -> 215.68345 | S54: =I21 -> 225.11521 | T54: =I22 -> 237.87842 | U54: =I23 -> 248.68337 | V54: =I24 -> 252.92064 | W54: =I25 -> 263.96915 | X54: =I26 -> 272.48328 | Y54: =I27 -> 289.0437 | Z54: =I28 -> 308.02691 | AA54: =I29 -> 324.05818 | AB54: =I30 -> 338.05428 | AC54: =I31 -> 353.67168 | AD54: =I32 -> 369.54437 | AE54: =I33 -> 394.1806 | AF54: =I34 -> 412.61131 | AG54: =I35 -> 428.51679 | AH54: =I36 -> 448.21939 | AI54: =I37 -> 465.25173
A55: 1999=100 | B55: =J4 -> 33.400197 | C55: =J5 -> 36.192663 | D55: =J6 -> 50.238757 | E55: =J7 -> 63.650885 | F55: =J8 -> 74.938536 | G55: =J9 -> 86.715918 | H55: =J10 -> 100 | I55: =J11 -> 110.69796 | J55: =J12 -> 117.86345 | K55: =J13 -> 124.34868 | L55: =J14 -> 129.67039 | M55: =J15 -> 140.19631 | N55: =J16 -> 148.44684 | O55: =J17 -> 157.51272 | P55: =J18 -> 167.16477 | Q55: =J19 -> 177.71351 | R55: =J20 -> 187.03188 | S55: =J21 -> 195.21072 | T55: =J22 -> 206.27845 | U55: =J23 -> 215.64807 | V55: =J24 -> 219.32246 | W55: =J25 -> 228.90327 | X55: =J26 -> 236.28638 | Y55: =J27 -> 250.64689 | Z55: =J28 -> 267.10837 | AA55: =J29 -> 281.01002 | AB55: =J30 -> 293.14687 | AC55: =J31 -> 306.68964 | AD55: =J32 -> 320.45379 | AE55: =J33 -> 341.81732 | AF55: =J34 -> 357.79969 | AG55: =J35 -> 371.59226 | AH55: =J36 -> 388.67756 | AI55: =J37 -> 403.44731
A56: 2000=100 | B56: =$K$4 -> 30.172368 | C56: =$K$5 -> 32.694967 | D56: =$K$6 -> 45.383632 | E56: =$K$7 -> 57.499598 | F56: =$K$8 -> 67.696399 | G56: =$K$9 -> 78.335603 | H56: =$K$10 -> 90.335898 | I56: =$K$11 -> 100 | J56: =$K$12 -> 106.47301 | K56: =$K$13 -> 112.3315 | L56: =$K$14 -> 117.13891 | M56: =$K$15 -> 126.6476 | N56: =$K$16 -> 134.10079 | O56: =$K$17 -> 142.29053 | P56: =$K$18 -> 151.0098 | Q56: =$K$19 -> 160.53909 | R56: =$K$20 -> 168.95693 | S56: =$K$21 -> 176.34536 | T56: =$K$22 -> 186.34349 | U56: =$K$23 -> 194.80762 | V56: =$K$24 -> 198.12691 | W56: =$K$25 -> 206.78182 | X56: =$K$26 -> 213.45142 | Y56: =$K$27 -> 226.42412 | Z56: =$K$28 -> 241.29474 | AA56: =$K$29 -> 253.85293 | AB56: =$K$30 -> 264.81686 | AC56: =$K$31 -> 277.05084 | AD56: =$K$32 -> 289.48481 | AE56: =K33 -> 308.78375 | AF56: =$K$34 -> 323.22156 | AG56: =K35 -> 335.68121 | AH56: =K36 -> 351.11536 | AI56: =K37 -> 364.45775
A57: 2001=100 | B57: =$L$4 -> 28.338044 | C57: =$L$5 -> 30.707282 | D57: =$L$6 -> 42.624542 | E57: =$L$7 -> 54.00392 | F57: =$L$8 -> 63.580808 | G57: =$L$9 -> 73.573203 | H57: =$L$10 -> 84.843942 | I57: =$L$11 -> 93.920516 | J57: =$L$12 -> 100 | K57: =$L$13 -> 105.50232 | L57: =$L$14 -> 110.01747 | M57: =$L$15 -> 118.94808 | N57: =$L$16 -> 125.94815 | O57: =$L$17 -> 133.64 | P57: =$L$18 -> 141.82918 | Q57: =$L$19 -> 150.77914 | R57: =$L$20 -> 158.68522 | S57: =$L$21 -> 165.62447 | T57: =$L$22 -> 175.01477 | U57: =$L$23 -> 182.96432 | V57: =$L$24 -> 186.08182 | W57: =$L$25 -> 194.21056 | X57: =$L$26 -> 200.47468 | Y57: =$L$27 -> 212.6587 | Z57: =$L$28 -> 226.62527 | AA57: =$L$29 -> 238.41998 | AB57: =$L$30 -> 248.71736 | AC57: =$L$31 -> 260.20758 | AD57: =$L$32 -> 271.88563 | AE57: =$L$33 -> 290.01129 | AF57: =$L$34 -> 303.57136 | AG57: =L35 -> 315.27352 | AH57: =L36 -> 329.76936 | AI57: =L37 -> 342.3006
A58: 2002=100 | B58: =$M$4 -> 26.860114 | C58: =$M$5 -> 29.105788 | D58: =$M$6 -> 40.401519 | E58: =$M$7 -> 51.187422 | F58: =$M$8 -> 60.264841 | G58: =$M$9 -> 69.736097 | H58: =$M$10 -> 80.419026 | I58: =$M$11 -> 89.022225 | J58: =$M$12 -> 94.784642 | K58: =$M$13 -> 100 | L58: =$M$14 -> 104.27967 | M58: =$M$15 -> 112.74451 | N58: =$M$16 -> 119.3795 | O58: =$M$17 -> 126.6702 | P58: =$M$18 -> 134.43228 | Q58: =$M$19 -> 142.91547 | R58: =$M$20 -> 150.40922 | S58: =$M$21 -> 156.98656 | T58: =$M$22 -> 165.88712 | U58: =$M$23 -> 173.42207 | V58: =$M$24 -> 176.37698 | W58: =$M$25 -> 184.08178 | X58: =$M$26 -> 190.01921 | Y58: =$M$27 -> 201.56779 | Z58: =$M$28 -> 214.80595 | AA58: =$M$29 -> 225.98552 | AB58: =$M$30 -> 235.74586 | AC58: =$M$31 -> 246.63682 | AD58: =$M$32 -> 257.70582 | AE58: =$M$33 -> 274.88616 | AF58: =$M$34 -> 287.73902 | AG58: =M35 -> 298.83088 | AH58: =M36 -> 312.57071 | AI58: =M37 -> 324.4484
A59: 2003=100 | B59: =$N$4 -> 25.757767 | C59: =$N$5 -> 27.911278 | D59: =$N$6 -> 38.743429 | E59: =$N$7 -> 49.086675 | F59: =$N$8 -> 57.791555 | G59: =$N$9 -> 66.874107 | H59: =$N$10 -> 77.118606 | I59: =$N$11 -> 85.368728 | J59: =$N$12 -> 90.894653 | K59: =$N$13 -> 95.895972 | L59: =$N$14 -> 100 | M59: =$N$15 -> 108.11744 | N59: =$N$16 -> 114.48014 | O59: =$N$17 -> 121.47161 | P59: =$N$18 -> 128.91514 | Q59: =$N$19 -> 137.05018 | R59: =$N$20 -> 144.23638 | S59: =$N$21 -> 150.54379 | T59: =$N$22 -> 159.07907 | U59: =$N$23 -> 166.30478 | V59: =$N$24 -> 169.13842 | W59: =$N$25 -> 176.52701 | X59: =$N$26 -> 182.22076 | Y59: =$N$27 -> 193.29539 | Z59: =$N$28 -> 205.99025 | AA59: =$N$29 -> 216.71101 | AB59: =$N$30 -> 226.07078 | AC59: =$N$31 -> 236.51478 | AD59: =$N$32 -> 247.1295 | AE59: =$N$33 -> 263.60476 | AF59: =$N$34 -> 275.93013 | AG59: =N35 -> 286.56678 | AH59: =N36 -> 299.74272 | AI59: =N37 -> 311.13294
A60: 2004=100 | B60: =$O$4 -> 23.823877 | C60: =$O$5 -> 25.815703 | D60: =$O$6 -> 35.834578 | E60: =$O$7 -> 45.401254 | F60: =$O$8 -> 53.452573 | G60: =$O$9 -> 61.853208 | H60: =$O$10 -> 71.328552 | I60: =$O$11 -> 78.959255 | J60: =$O$12 -> 84.070295 | K60: =$O$13 -> 88.696115 | L60: =$O$14 -> 92.492013 | M60: =$O$15 -> 100 | N60: =$O$16 -> 105.88498 | O60: =$O$17 -> 112.35154 | P60: =$O$18 -> 119.23621 | Q60: =$O$19 -> 126.76047 | R60: =$O$20 -> 133.40713 | S60: =$O$21 -> 139.24098 | T60: =$O$22 -> 147.13543 | U60: =$O$23 -> 153.81864 | V60: =$O$24 -> 156.43953 | W60: =$O$25 -> 163.27339 | X60: =$O$26 -> 168.53965 | Y60: =$O$27 -> 178.7828 | Z60: =$O$28 -> 190.52453 | AA60: =$O$29 -> 200.44038 | AB60: =$O$30 -> 209.09742 | AC60: =$O$31 -> 218.75728 | AD60: =$O$32 -> 228.57505 | AE60: =$O$33 -> 243.81335 | AF60: =$O$34 -> 255.21334 | AG60: =O35 -> 265.05138 | AH60: =O36 -> 277.23807 | AI60: =O37 -> 287.77312
A61: 2005=100 | B61: =$P$4 -> 22.49977 | C61: =$P$5 -> 24.380891 | D61: =$P$6 -> 33.842928 | E61: =$P$7 -> 42.877897 | F61: =$P$8 -> 50.481731 | G61: =$P$9 -> 58.415468 | H61: =$P$10 -> 67.364181 | I61: =$P$11 -> 74.570778 | J61: =$P$12 -> 79.397751 | K61: =$P$13 -> 83.766472 | L61: =$P$14 -> 87.351399 | M61: =$P$15 -> 94.442099 | N61: =$P$16 -> 100 | O61: =$P$17 -> 106.10715 | P61: =$P$18 -> 112.60918 | Q61: =$P$19 -> 119.71525 | R61: =$P$20 -> 125.9925 | S61: =$P$21 -> 131.5021 | T61: =$P$22 -> 138.95779 | U61: =$P$23 -> 145.26955 | V61: =$P$24 -> 147.74478 | W61: =$P$25 -> 154.19881 | X61: =$P$26 -> 159.17239 | Y61: =$P$27 -> 168.84623 | Z61: =$P$28 -> 179.93536 | AA61: =$P$29 -> 189.3001 | AB61: =$P$30 -> 197.47599 | AC61: =$P$31 -> 206.59897 | AD61: =$P$32 -> 215.87107 | AE61: =$P$33 -> 230.26244 | AF61: =$P$34 -> 241.02883 | AG61: =P35 -> 250.32009 | AH61: =P36 -> 261.82946 | AI61: =P37 -> 271.77898
A62: 2006=100 | B62: =$Q$4 -> 21.204762 | C62: =$Q$5 -> 22.977613 | D62: =$Q$6 -> 31.895048 | E62: =$Q$7 -> 40.409997 | F62: =$Q$8 -> 47.576181 | G62: =$Q$9 -> 55.053279 | H62: =$Q$10 -> 63.486936 | I62: =$Q$11 -> 70.278746 | J62: =$Q$12 -> 74.827896 | K62: =$Q$13 -> 78.945169 | L62: =$Q$14 -> 82.32376 | M62: =$Q$15 -> 89.006344 | N62: =$Q$16 -> 94.244352 | O62: =$Q$17 -> 100 | P62: =$Q$18 -> 106.12779 | Q62: =$Q$19 -> 112.82486 | R62: =$Q$20 -> 118.74081 | S62: =$Q$21 -> 123.93331 | T62: =$Q$22 -> 130.95987 | U62: =$Q$23 -> 136.90835 | V62: =$Q$24 -> 139.24111 | W62: =$Q$25 -> 145.32367 | X62: =$Q$26 -> 150.01098 | Y62: =$Q$27 -> 159.12803 | Z62: =$Q$28 -> 169.57892 | AA62: =$Q$29 -> 178.40465 | AB62: =$Q$30 -> 186.10997 | AC62: =$Q$31 -> 194.70786 | AD62: =$Q$32 -> 203.44629 | AE62: =$Q$33 -> 217.00934 | AF62: =$Q$34 -> 227.15606 | AG62: =Q35 -> 235.91254 | AH62: =Q36 -> 246.75947 | AI62: =Q37 -> 256.13633
A63: 2007=100 | B63: =$R$4 -> 19.980404 | C63: =$R$5 -> 21.650892 | D63: =$R$6 -> 30.053436 | E63: =$R$7 -> 38.076733 | F63: =$R$8 -> 44.829144 | G63: =$R$9 -> 51.874517 | H63: =$R$10 -> 59.821216 | I63: =$R$11 -> 66.220869 | J63: =$R$12 -> 70.507352 | K63: =$R$13 -> 74.386895 | L63: =$R$14 -> 77.570406 | M63: =$R$15 -> 83.86714 | N63: =$R$16 -> 88.802707 | O63: =$R$17 -> 94.226025 | P63: =$R$18 -> 100 | Q63: =$R$19 -> 106.31038 | R63: =$R$20 -> 111.88475 | S63: =$R$21 -> 116.77743 | T63: =$R$22 -> 123.39828 | U63: =$R$23 -> 129.0033 | V63: =$R$24 -> 131.20136 | W63: =$R$25 -> 136.93272 | X63: =$R$26 -> 141.34939 | Y63: =$R$27 -> 149.94002 | Z63: =$R$28 -> 159.78747 | AA63: =$R$29 -> 168.10361 | AB63: =$R$30 -> 175.36403 | AC63: =$R$31 -> 183.46548 | AD63: =$R$32 -> 191.69936 | AE63: =$R$33 -> 204.47928 | AF63: =$R$34 -> 214.04013 | AG63: =R35 -> 222.29101 | AH63: =R36 -> 232.51164 | AI63: =R37 -> 241.34709
A64: 2008=100 | B64: =$S$4 -> 18.794406 | C64: =$S$5 -> 20.365736 | D64: =$S$6 -> 28.269521 | E64: =$S$7 -> 35.816571 | F64: =$S$8 -> 42.168171 | G64: =$S$9 -> 48.795344 | H64: =$S$10 -> 56.270343 | I64: =$S$11 -> 62.290124 | J64: =$S$12 -> 66.32217 | K64: =$S$13 -> 69.97143 | L64: =$S$14 -> 72.965975 | M64: =$S$15 -> 78.888946 | N64: =$S$16 -> 83.531547 | O64: =$S$17 -> 88.632948 | P64: =$S$18 -> 94.064191 | Q64: =$S$19 -> 100 | R64: =$S$20 -> 105.24348 | S64: =$S$21 -> 109.84574 | T64: =$S$22 -> 116.07359 | U64: =$S$23 -> 121.34591 | V64: =$S$24 -> 123.4135 | W64: =$S$25 -> 128.80465 | X64: =$S$26 -> 132.95916 | Y64: =$S$27 -> 141.03987 | Z64: =$S$28 -> 150.30279 | AA64: =$S$29 -> 158.1253 | AB64: =$S$30 -> 164.95475 | AC64: =$S$31 -> 172.57531 | AD64: =$S$32 -> 180.32045 | AE64: =$S$33 -> 192.34178 | AF64: =$S$34 -> 201.33511 | AG64: =S35 -> 209.09624 | AH64: =S36 -> 218.7102 | AI64: =S37 -> 227.02118
A65: 2009=100 | B65: =$T$4 -> 17.858023 | C65: =$T$5 -> 19.351066 | D65: =$T$6 -> 26.861066 | E65: =$T$7 -> 34.032104 | F65: =$T$8 -> 40.067252 | G65: =$T$9 -> 46.364243 | H65: =$T$10 -> 53.46682 | I65: =$T$11 -> 59.186681 | J65: =$T$12 -> 63.01784 | K65: =$T$13 -> 66.485286 | L65: =$T$14 -> 69.330635 | M65: =$T$15 -> 74.95851 | N65: =$T$16 -> 79.369805 | O65: =$T$17 -> 84.217042 | P65: =$T$18 -> 89.377687 | Q65: =$T$19 -> 95.01776 | R65: =$T$20 -> 100 | S65: =$T$21 -> 104.37296 | T65: =$T$22 -> 110.29053 | U65: =$T$23 -> 115.30016 | V65: =$T$24 -> 117.26474 | W65: =$T$25 -> 122.3873 | X65: =$T$26 -> 126.33481 | Y65: =$T$27 -> 134.01292 | Z65: =$T$28 -> 142.81435 | AA65: =$T$29 -> 150.24712 | AB65: =$T$30 -> 156.73631 | AC65: =$T$31 -> 163.9772 | AD65: =$T$32 -> 171.33645 | AE65: =$T$33 -> 182.75885 | AF65: =$T$34 -> 191.30411 | AG65: =T35 -> 198.67857 | AH65: =T36 -> 207.81353 | AI65: =T37 -> 215.71044
...

Sheet Original INEGI Base 1993-2025
A1: http://www.inegi.org.mx/sistemas/bie/
A2: Cuentas nacionales > Producto interno bruto trimestral, base 2018 > Índice acumulado de precios implícitos, 2018 = 100
A3: Unidad de medida:Índice base 2018 = 100
A4: Periodicidad: Trimestral
A5: Periodo | B5: Base 2018
A6: 1993/01 | B6: 11.564787 | D6: 1993/04
A7: 1993/02 | B7: 11.705226 | D7: 1994/04
A8: 1993/03 | B8: 11.80045 | D8: 1995/04
A9: 1993/04 | B9: 11.885767 | D9: 1996/04
A10: 1994/01 | B10: 12.412881 | D10: 1997/04
A11: 1994/02 | B11: 12.570247 | D11: 1998/04
A12: 1994/03 | B12: 12.701641 | D12: 1999/04
A13: 1994/04 | B13: 12.879492 | D13: 2000/04
A14: 1995/01 | B14: 15.139769 | D14: 2001/04
A15: 1995/02 | B15: 16.401396 | D15: 2002/04
A16: 1995/03 | B16: 17.148405 | D16: 2003/04
A17: 1995/04 | B17: 17.877924 | D17: 2004/04
... A39: 2001/02 | B39: 41.472395 | D39: 2026/04
A40: 2001/03 | B40: 41.727504
A41: 2001/04 | B41: 41.942794
A42: 2002/01 | B42: 42.797503
A43: 2002/02 | B43: 43.454759
A44: 2002/03 | B44: 43.878896
A45: 2002/04 | B45: 44.250622
A46: 2003/01 | B46: 45.96146
A47: 2003/02 | B47: 45.801193
A48: 2003/03 | B48: 45.858355
A49: 2003/04 | B49: 46.144402
A50: 2004/01 | B50: 48.010914
A51: 2004/02 | B51: 48.742113
... A137: 2025/04 | B137: 138.31448
A138: 2026/01
A139: 2026/02
A140: 2026/03
A141: 2026/04
